<mujoco model="atom">
  <compiler angle="radian" meshdir="meshes/"/>

  <size njmax="500" nconmax="100" />
  <default>
    <!-- <joint damping="0.001" armature="0.01" frictionloss="0.1"/> -->
    <joint actuatorfrclimited="true" type="hinge" armature="0.01" frictionloss="0.1" damping="0.001"/>


    <default class="visual">
      <geom type="mesh" contype="0" conaffinity="0" group="0" density="0" />
    </default>

    <default class="collision">
        <geom group="3" rgba=".2 .6 .2 .3" contype="1" conaffinity="1"/>
    </default>
    <default class="mimic">
        <site group="4" type="box" size="0.075 0.05 0.025" rgba="1.0 0.0 0.0 0.5"/>
    </default>

  </default>

  <asset>
    <material name="black" rgba="0.1 0.1 0.1 1"/>
    <material name="white" rgba="1 1 1 1"/>

    <mesh name="pelvis" file="pelvis.STL"/>
    <mesh name="leg_l1_link" file="leg_l1_link.STL"/>
    <mesh name="leg_l2_link" file="leg_l2_link.STL"/>
    <mesh name="leg_l3_link" file="leg_l3_link.STL"/>
    <mesh name="leg_l4_link" file="leg_l4_link.STL"/>
    <mesh name="leg_l5_link" file="leg_l5_link.STL"/>
    <mesh name="leg_l6_link" file="leg_l6_link.STL"/>
    <mesh name="leg_r1_link" file="leg_r1_link.STL"/>
    <mesh name="leg_r2_link" file="leg_r2_link.STL"/>
    <mesh name="leg_r3_link" file="leg_r3_link.STL"/>
    <mesh name="leg_r4_link" file="leg_r4_link.STL"/>
    <mesh name="leg_r5_link" file="leg_r5_link.STL"/>
    <mesh name="leg_r6_link" file="leg_r6_link.STL"/>
    <mesh name="torso_link" file="torso_link.STL"/>
    <mesh name="left_shoulder_pitch_link" file="left_shoulder_pitch_link.STL"/>
    <mesh name="left_shoulder_roll_link" file="left_shoulder_roll_link.STL"/>
    <mesh name="left_shoulder_yaw_link" file="left_shoulder_yaw_link.STL"/>
    <mesh name="left_elbow_pitch_link" file="left_elbow_pitch_link.STL"/>
    <mesh name="left_elbow_roll_link" file="left_elbow_roll_link.STL"/>
    <mesh name="left_wrist_pitch_link" file="left_wrist_pitch_link.STL"/>
    <mesh name="left_wrist_yaw_link" file="left_wrist_yaw_link.STL"/>
    <!-- removed hand meshes (left) to avoid loading missing files
    <mesh name="L_hand_base_link" file="L_hand_base_link.STL"/>
    <mesh name="Link11_L" file="Link11_L.STL"/>
    <mesh name="Link12_L" file="Link12_L.STL"/>
    <mesh name="Link13_L" file="Link13_L.STL"/>
    <mesh name="Link16_L" file="Link16_L.STL"/>
    <mesh name="Link17_L" file="Link17_L.STL"/>
    <mesh name="Link18_L" file="Link18_L.STL"/>
    <mesh name="Link19_L" file="Link19_L.STL"/>
    <mesh name="Link20_L" file="Link20_L.STL"/>
    <mesh name="Link21_L" file="Link21_L.STL"/>
    <mesh name="Link22_L" file="Link22_L.STL"/>
    -->
    <mesh name="right_shoulder_pitch_link" file="right_shoulder_pitch_link.STL"/>
    <mesh name="right_shoulder_roll_link" file="right_shoulder_roll_link.STL"/>
    <mesh name="right_shoulder_yaw_link" file="right_shoulder_yaw_link.STL"/>
    <mesh name="right_elbow_pitch_link" file="right_elbow_pitch_link.STL"/>
    <mesh name="right_elbow_roll_link" file="right_elbow_roll_link.STL"/>
    <mesh name="right_wrist_pitch_link" file="right_wrist_pitch_link.STL"/>
    <mesh name="right_wrist_yaw_link" file="right_wrist_yaw_link.STL"/>
    <!-- removed hand meshes (right) to avoid loading missing files
    <mesh name="R_hand_base_link" file="R_hand_base_link.STL"/>
    <mesh name="Link11_R" file="Link11_R.STL"/>
    <mesh name="Link12_R" file="Link12_R.STL"/>
    <mesh name="Link13_R" file="Link13_R.STL"/>
    <mesh name="Link14_R" file="Link14_R.STL"/>
    <mesh name="Link15_R" file="Link15_R.STL"/>
    <mesh name="Link16_R" file="Link16_R.STL"/>
    <mesh name="Link17_R" file="Link17_R.STL"/>
    <mesh name="Link18_R" file="Link18_R.STL"/>
    <mesh name="Link19_R" file="Link19_R.STL"/>
    <mesh name="Link20_R" file="Link20_R.STL"/>
    <mesh name="Link21_R" file="Link21_R.STL"/>
    <mesh name="Link22_R" file="Link22_R.STL"/>
    -->
    <mesh name="head_yaw_link" file="head_yaw_link.STL"/>
    <mesh name="head_pitch_link" file="head_pitch_link.STL"/>
  </asset>

  <worldbody>
    <body name="pelvis" pos="0 0 0.98">
      <site name="pelvis_mimic" class="mimic"/>
      <inertial pos="0.0006 0 -0.0998" quat="0.999993 0 -0.00384584 0" mass="6.537" diaginertia="0.0344008 0.0292 0.0213992"/>
      <joint name="root" type="free" limited="false" actuatorfrclimited="false"/>
      <geom class="visual" mesh="pelvis"/>
      <geom name="pelvis_collision" class="collision" type="sphere" size="0.085" pos="0 0 -0.12"/>

      <site name="imu_in_pelvis" size="0.01" pos="0.0 0.0 -0.18"/>
      <body name="left_hip_pitch_link" pos="0 0.0745 -0.133">
        <site name="left_hip_mimic" class="mimic"  pos="0.0 0.08 -0.02"/>
        <inertial pos="0.0011 0.037 -0.0046" quat="0.121199 0.673028 0.2758 0.675484" mass="0.6084" diaginertia="0.00182702 0.00139444 0.000978541"/>
        <joint name="left_hip_pitch_joint" pos="0 0 0" axis="0 1 0" range="-2.5656 3.0194" actuatorfrcrange="-280 280" armature="0.10897986"/>
        <geom class="visual" mesh="leg_l1_link"/>
        <body name="left_hip_roll_link" pos="0.00283008 0.0765 -0.0248393" quat="0.998392 0 -0.0566928 0">
          <inertial pos="-0.006 -0.0003 -0.0057" quat="0.699481 -0.103571 0.103571 0.699481" mass="2.267" diaginertia="0.00333028 0.0032 0.00296972"/>
          <joint name="left_hip_roll_joint" pos="0 0 0" axis="1 0 0" range="-0.2618 1.6581" actuatorfrcrange="-308 308" armature="0.070622376"/>
          <geom class="visual" mesh="leg_l2_link"/>
          <geom name="left_thigh" class="collision" type="capsule" size="0.05" fromto="0.0 0 0  -0.01 0 -0.3"/>

          <body name="left_hip_yaw_link" pos="0 -0.02 -0.065">
            <inertial pos="-0.0023 0.0113 -0.1214" quat="0.479916 0.0431402 0.00127312 0.876252" mass="5.553" diaginertia="0.0418335 0.0411911 0.0114755"/>
            <joint name="left_hip_yaw_joint" pos="0 0 0" axis="0 0 1" range="-2.7925 2.7925" actuatorfrcrange="-140 140" armature="0.036700268"/>
            <geom class="visual" mesh="leg_l3_link"/>
            <body name="left_knee_link" pos="-0.0468661 0 -0.321339">
              <site name="left_knee_mimic" class="mimic" quat="0.99838 0 0.0568972 0"/>
              <inertial pos="-0.0125 -0.0005 -0.104" quat="0.998306 0.00153276 0.0490998 -0.0311667" mass="3.1" diaginertia="0.0190581 0.0189 0.00264192"/>
              <joint name="left_knee_joint" pos="0 0 0" axis="0 1 0" range="0 2.4871" actuatorfrcrange="-360 360" armature="0.0812586105"/>
              <geom class="visual" mesh="leg_l4_link"/>
              <!-- <geom class="collision" size="0.04 0.04 0.16" pos="0 0 -0.16" quat="0.998392 0 0.0566928 0" type="box" rgba="1 1 1 1"/> -->
              <geom name="left_shin" class="collision" type="capsule" size="0.04" fromto="0.0 0 0 -0.02 0 -0.25"/>

              <body name="left_ankle_pitch_link" pos="-0.0319616 0 -0.333526" quat="0.998392 0 0.0566928 0">
                <inertial pos="9.1e-05 0.000214 -0.013313" mass="0.1552" diaginertia="4.2e-05 3.7e-05 2.3e-05"/>
                <joint name="left_ankle_pitch_joint" pos="0 0 0" axis="0 1 0" range="-0.8727 0.5236" actuatorfrcrange="-130 130" armature="0.01536"/>
                <geom class="visual" mesh="leg_l5_link"/>
                <body name="left_ankle_roll_link" pos="0 0 -0.025">
                  <site name="left_foot_mimic" class="mimic" pos="0.0 0.0 -0.04"/>
                  <inertial pos="0.0318 0 -0.0352" quat="0 0.720547 0 0.693406" mass="0.6943" diaginertia="0.00330384 0.0032 0.00069616"/>
                  <joint name="left_ankle_roll_joint" pos="0 0 0" axis="1 0 0" range="-0.48 0.48" actuatorfrcrange="-130 130" armature="0.01536"/>
                  <geom class="visual" mesh="leg_l6_link"/>
                  <!-- <geom class="collision" size="0.125 0.05 0.01" pos="0.04 0 -0.056" type="box" rgba="1 1 1 1"/> -->
                  <geom name="left_foot1_collision" type="capsule" size="0.01" class="collision" fromto="0.12 -0.026 -0.056 0.05 -0.027 -0.056"/>
                  <geom name="left_foot2_collision" type="capsule" size="0.01" class="collision" fromto="-0.064 -0.018 -0.056 0.142 -0.018 -0.056"/>
                  <geom name="left_foot3_collision" type="capsule" size="0.01" class="collision" fromto="-0.072 -0.01 -0.056 0.148 -0.01 -0.056"/>
                  <geom name="left_foot4_collision" type="capsule" size="0.01" class="collision" fromto="-0.074 0 -0.056 0.15 0 -0.056"/>
                  <geom name="left_foot5_collision" type="capsule" size="0.01" class="collision" fromto="-0.072 0.01 -0.056 0.148 0.01 -0.056"/>
                  <geom name="left_foot6_collision" type="capsule" size="0.01" class="collision" fromto="-0.064 0.018 -0.056 0.142 0.018 -0.056"/>
                  <geom name="left_foot7_collision" type="capsule" size="0.01" class="collision" fromto="0.12 0.026 -0.056 0.05 0.026 -0.056"/>
                </body>
              </body>
            </body>
          </body>
        </body>
      </body>
      <body name="right_hip_pitch_link" pos="0 -0.0745 -0.133">
        <site name="right_hip_mimic" class="mimic"  pos="0.0 -0.08 -0.02"/>
        <inertial pos="0.0011 -0.037 -0.0046" quat="-0.121199 0.673028 -0.2758 0.675484" mass="0.6084" diaginertia="0.00182702 0.00139444 0.000978541"/>
        <joint name="right_hip_pitch_joint" pos="0 0 0" axis="0 1 0" range="-2.5656 3.0194" actuatorfrcrange="-280 280" armature="0.10897986"/>
        <geom class="visual" mesh="leg_r1_link"/>
        <body name="right_hip_roll_link" pos="0.00283008 -0.0765 -0.0248393" quat="0.998392 0 -0.0566928 0">
          <inertial pos="-0.006 0.0003 -0.0057" quat="0.699481 0.103571 -0.103571 0.699481" mass="2.267" diaginertia="0.00333028 0.0032 0.00296972"/>
          <joint name="right_hip_roll_joint" pos="0 0 0" axis="1 0 0" range="-1.6581 0.2618" actuatorfrcrange="-308 308" armature="0.070622376"/>
          <geom class="visual" mesh="leg_r2_link"/>
          <geom name="right_thigh" class="collision" type="capsule" size="0.05" fromto="0.0 0 0  -0.01 0 -0.3"/>

          <body name="right_hip_yaw_link" pos="0 0.02 -0.065">
            <inertial pos="-0.0023 -0.0113 -0.1214" quat="0.876252 0.00127312 0.0431402 0.479916" mass="5.553" diaginertia="0.0418335 0.0411911 0.0114755"/>
            <joint name="right_hip_yaw_joint" pos="0 0 0" axis="0 0 1" range="-2.7925 2.7925" actuatorfrcrange="-140 140" armature="0.036700268"/>
            <geom class="visual" mesh="leg_r3_link"/>
            <body name="right_knee_link" pos="-0.0468661 0 -0.321339">
              <inertial pos="-0.0125 0.0005 -0.104" quat="0.998306 -0.00153276 0.0490998 0.0311667" mass="3.1" diaginertia="0.0190581 0.0189 0.00264192"/>
              <joint name="right_knee_joint" pos="0 0 0" axis="0 1 0" range="0 2.4871" actuatorfrcrange="-360 360" armature="0.0812586105"/>
              <site name="right_knee_mimic" class="mimic" quat="0.99838 0 0.0568972 0"/>
              <geom class="visual" mesh="leg_r4_link"/>
              <geom name="right_shin" class="collision" type="capsule" size="0.04" fromto="0.0 0 0 -0.02 0 -0.25"/>
              <body name="right_ankle_pitch_link" pos="-0.0319616 0 -0.333526" quat="0.998392 0 0.0566928 0">
                <inertial pos="9.1e-05 -0.000214 -0.013313" mass="0.1552" diaginertia="4.2e-05 3.7e-05 2.3e-05"/>
                <joint name="right_ankle_pitch_joint" pos="0 0 0" axis="0 1 0" range="-0.8727 0.5236" actuatorfrcrange="-130 130" armature="0.01536"/>
                <geom class="visual" mesh="leg_r5_link"/>
                <body name="right_ankle_roll_link" pos="0 0 -0.025">
                  <site name="right_foot_mimic" class="mimic" pos="0.0 0.0 -0.04"/>
                  <inertial pos="0.0318 0 -0.0352" quat="0 0.720547 0 0.693406" mass="0.6943" diaginertia="0.00330384 0.0032 0.00069616"/>
                  <joint name="right_ankle_roll_joint" pos="0 0 0" axis="1 0 0" range="-0.48 0.48" actuatorfrcrange="-130 130" armature="0.01536"/>
                  <geom class="visual" mesh="leg_r6_link"/>
                  <!-- <geom class="collision" size="0.125 0.05 0.01" pos="0.04 0 -0.056" type="box" rgba="1 1 1 1"/> -->
                  <geom name="right_foot1_collision" type="capsule" size="0.01" class="collision" fromto="0.12 -0.026 -0.056 0.05 -0.027 -0.056"/>
                  <geom name="right_foot2_collision" type="capsule" size="0.01" class="collision" fromto="-0.064 -0.018 -0.056 0.142 -0.018 -0.056"/>
                  <geom name="right_foot3_collision" type="capsule" size="0.01" class="collision" fromto="-0.072 -0.01 -0.056 0.148 -0.01 -0.056"/>
                  <geom name="right_foot4_collision" type="capsule" size="0.01" class="collision" fromto="-0.074 0 -0.056 0.15 0 -0.056"/>
                  <geom name="right_foot5_collision" type="capsule" size="0.01" class="collision" fromto="-0.072 0.01 -0.056 0.148 0.01 -0.056"/>
                  <geom name="right_foot6_collision" type="capsule" size="0.01" class="collision" fromto="-0.064 0.018 -0.056 0.142 0.018 -0.056"/>
                  <geom name="right_foot7_collision" type="capsule" size="0.01" class="collision" fromto="0.12 0.026 -0.056 0.05 0.026 -0.056"/>
                </body>
              </body>
            </body>
          </body>
        </body>
      </body>
    <body name="torso_link">
        <site name="upper_body_mimic" class="mimic" pos="0.0 0.0 0.25"/>
        <inertial pos="-0.0155931 0 0.219905" quat="0.707104 0.00193671 0.00193671 0.707104" mass="14.0858" diaginertia="0.1671325 0.1806563 0.067207"/>
        <joint name="waist_yaw_joint" pos="0 0 0" axis="0 0 1" range="-2.7925 2.7925" actuatorfrcrange="-250 250" armature="0.1123945708"/>
        <geom class="visual" mesh="torso_link"/>
        <geom name="torso_collision1" class="collision" type="capsule" size="0.09" fromto="0.005 -0.032 .3 0.005 0.032 .3"/>
        <geom name="torso_collision2" class="collision" type="capsule" size="0.085" fromto="0.005 -0.028 .2 0.005 0.028 .2"/>
        <geom name="torso_collision3" class="collision" type="capsule" size="0.07" fromto="0.005 -0.02 .06 0.005 0.02 .06"/>

        <!-- head links as fixed bodies to match URDF inertials -->
        <body name="head_yaw_link" pos="0 0 0.4177">
          <inertial pos="0.0000 -0.0027 0.0383" mass="0.4387" diaginertia="0.0003 0.0002 0.0002"/>
          <geom class="visual" type="mesh" mesh="head_yaw_link"/>
          <body name="head_pitch_link" pos="0 0 0.0">
            <inertial pos="0.0337 0.0004 0.1204" mass="1.3341" diaginertia="0.0042 0.0070 0.0067"/>
            <geom class="visual" type="mesh" mesh="head_pitch_link"/>
          </body>
        </body>

        <body name="left_shoulder_pitch_link" pos="0 0.128 0.333">
          <inertial pos="0.0044 0.0368 0" quat="0.0878415 0.57587 -0.237641 0.777293" mass="0.4473" diaginertia="0.00103429 0.000847068 0.000618639"/>
          <joint name="left_shoulder_pitch_joint" pos="0 0 0" axis="0 1 0" range="-2.97 2.97" actuatorfrcrange="-56 56" armature="24.001"/>
          <geom class="visual" mesh="left_shoulder_pitch_link"/>
          <body name="left_shoulder_roll_link" pos="0 0.078 0" >
            <site name="left_shoulder_mimic" class="mimic"/>
            <inertial pos="0.0124 0.0009 -0.0545" quat="0.706611 -0.0264772 -0.0264772 0.706611" mass="1.794" diaginertia="0.0067 0.00663002 0.00126998"/>
            <joint name="left_shoulder_roll_joint" pos="0 0 0" axis="1 0 0" range="-0.43 3.14" actuatorfrcrange="-36 36" armature="24.001"/>
            <geom class="visual" mesh="left_shoulder_roll_link"/>
            <body name="left_shoulder_yaw_link" pos="0 0 -0.135">
              <inertial pos="-0.0014 0.0066 -0.1179" quat="0.996622 -0.0589197 0.050134 0.0275679" mass="0.9798" diaginertia="0.00181039 0.00161157 0.000778049"/>
              <joint name="left_shoulder_yaw_joint" pos="0 0 0" axis="0 0 1" range="-2.97 2.97" actuatorfrcrange="-36 36" armature="24.001"/>
              <geom class="visual" mesh="left_shoulder_yaw_link"/>
              <geom name="left_shoulder_yaw_collision" class="collision" type="capsule" size="0.035" fromto="0 0 -0.06 0 0 0.12"/>

              <body name="left_elbow_pitch_link" pos="0.000441988 0 -0.13">
                <site name="left_elbow_mimic" class="mimic"/>
                <inertial pos="0.0903 0.0016 -0.0003" quat="-0.0206991 0.706804 0.0206991 0.706804" mass="0.8548" diaginertia="0.0028 0.00250586 0.000794138"/>
                <joint name="left_elbow_pitch_joint" pos="0 0 0" axis="0 1 0" range="-1.57 2" actuatorfrcrange="-36 36" armature="24.001"/>
                <geom class="visual" mesh="left_elbow_pitch_link"/>
                <geom name="left_elbow_pitch_collision" class="collision" type="capsule" size="0.035" fromto="-0.01 0 -0.01 0.24 0 -0.01"/>

                <body name="left_elbow_roll_link" pos="0.1453 0 0">
                  <inertial pos="0.027 0.0018 -0.0002" quat="0.707107 0.707107 0 0" mass="0.2126" diaginertia="0.0003 0.0003 0.0002"/>
                  <joint name="left_elbow_roll_joint" pos="0 0 0" axis="1 0 0" range="-2.97 2.97" actuatorfrcrange="-18.6 18.6" armature="7.302"/>
                  <geom class="visual" mesh="left_elbow_roll_link"/>
                  <body name="left_wrist_pitch_link" pos="0.05345 0 0">
                    <inertial pos="0.0421 -0.0042 -0.0038" quat="-0.252225 0.608925 -0.2878 0.694812" mass="1.2573" diaginertia="0.00293743 0.0029 0.000762572"/>
                    <joint name="left_wrist_pitch_joint" pos="0 0 0" axis="0 1 0" range="-1.57 1.57" actuatorfrcrange="-18.6 18.6" armature="7.302"/>
                    <geom class="visual" mesh="left_wrist_pitch_link"/>
                    <body name="left_wrist_yaw_link" pos="0.085 0 0">
                      <site name="left_hand_mimic" class="mimic" pos="0.1 0.0 0.0"/>
                      <inertial pos="0.0687936 -0.00112615 0.00198345" quat="0.486734 0.523302 0.46168 0.525449" mass="0.334" diaginertia="0.0003 0.0004 0.0003"/>
                      <joint name="left_wrist_yaw_joint" pos="0 0 0" axis="0 0 1" range="-1.57 1.57" actuatorfrcrange="-18.6 18.6" armature="7.302"/>
                      <geom class="visual" mesh="left_wrist_yaw_link"/>
                      <!-- Removed hand visuals and collision for left hand to match URDF -->
                      <!-- <geom pos="0.052 0 0" quat="0.707107 0 0 0.707107" class="visual" mesh="L_hand_base_link"/> -->
                      <!-- <geom name="left_hand_collision" class="collision" type="capsule" size="0.05" fromto="0.05 0 0 0.15 0 0"/> -->
                      <!-- <geom pos="0.1211 -0.01696 0.02045" quat="-2.59735e-06 0.707107 0 0.707107" class="visual" mesh="Link11_L"/> -->
                      <!-- <geom pos="0.1122 -0.0267843 0.0304367" quat="0.45591 0.540506 -0.540505 0.45591" class="visual" mesh="Link12_L"/> -->
                      <!-- <geom pos="0.146753 -0.0334252 0.0740107" quat="0.45591 0.540506 -0.540505 0.45591" class="visual" mesh="Link13_L"/> -->
                      <!-- <geom pos="0.220586 -0.00213757 0.0323868" quat="0.706999 -0.0123409 -0.0123409 0.706999" class="visual" mesh="Link16_L"/> -->
                      <!-- <geom pos="0.1891 0.00028533 0.01295" quat="0.707107 0 0 0.707107" class="visual" mesh="Link17_L"/> -->
                      <!-- <geom pos="0.221141 -0.00213757 0.01195" quat="0.707107 0 0 0.707107" class="visual" mesh="Link18_L"/> -->
                      <!-- <geom pos="0.18891 0.00028533 -0.0062872" quat="0.706864 0.0185099 0.0185099 0.706864" class="visual" mesh="Link19_L"/> -->
                      <!-- <geom pos="0.220855 -0.00213757 -0.00896273" quat="0.706864 0.0185099 0.0185099 0.706864" class="visual" mesh="Link20_L"/> -->
                      <!-- <geom pos="0.18771 0.00028533 -0.025488" quat="0.706138 0.0370072 0.0370072 0.706138" class="visual" mesh="Link21_L"/> -->
                      <!-- <geom pos="0.219471 -0.00213757 -0.0298317" quat="0.706138 0.0370072 0.0370072 0.706138" class="visual" mesh="Link22_L"/> -->

                    </body>
                  </body>
                </body>
              </body>
            </body>
          </body>
        </body>
        <body name="right_shoulder_pitch_link" pos="0 -0.128 0.333">
          <inertial pos="0.0044 -0.0368 0" quat="-0.0878415 0.57587 0.237641 0.777293" mass="0.4473" diaginertia="0.00103429 0.000847068 0.000618639"/>
          <joint name="right_shoulder_pitch_joint" pos="0 0 0" axis="0 1 0" range="-2.97 2.97" actuatorfrcrange="-56 56" armature="24.001" />
          <geom class="visual" mesh="right_shoulder_pitch_link"/>
          <body name="right_shoulder_roll_link" pos="0 -0.078 0">
            <site name="right_shoulder_mimic" class="mimic"/>
            <inertial pos="0.0124 -0.0009 -0.0545" quat="0.706611 -0.0264772 -0.0264772 0.706611" mass="1.794" diaginertia="0.0067 0.00663002 0.00126998"/>
            <joint name="right_shoulder_roll_joint" pos="0 0 0" axis="1 0 0" range="-3.14 0.43" actuatorfrcrange="-36 36" armature="24.001"/>
            <geom class="visual" mesh="right_shoulder_roll_link"/>
            <body name="right_shoulder_yaw_link" pos="0 0 -0.135">
              <inertial pos="-0.0014 -0.0066 -0.1179" quat="0.996622 0.0589197 0.050134 -0.0275679" mass="0.9798" diaginertia="0.00181039 0.00161157 0.000778049"/>
              <joint name="right_shoulder_yaw_joint" pos="0 0 0" axis="0 0 1" range="-2.97 2.97" actuatorfrcrange="-36 36" armature="24.001"/>
              <geom class="visual" mesh="right_shoulder_yaw_link"/>
              <geom name="right_shoulder_yaw_collision" class="collision" type="capsule" size="0.035" fromto="0 0 -0.06 0 0 0.12"/>

              <body name="right_elbow_pitch_link" pos="0.000441988 0 -0.13">
                <site name="right_elbow_mimic" class="mimic"/>
                <inertial pos="0.0903 -0.0016 -0.0003" quat="0.0206991 0.706804 -0.0206991 0.706804" mass="0.8548" diaginertia="0.0028 0.00250586 0.000794138"/>
                <joint name="right_elbow_pitch_joint" pos="0 0 0" axis="0 1 0" range="-1.57 2" actuatorfrcrange="-36 36" armature="24.001"/>
                <geom class="visual" mesh="right_elbow_pitch_link"/>
                <geom name="right_elbow_pitch_collision" class="collision" type="capsule" size="0.035" fromto="-0.01 0 -0.01 0.24 0 -0.01"/>

                <body name="right_elbow_roll_link" pos="0.145294 0 0">
                  <inertial pos="0.027 -0.0018 -0.0002" quat="0.707107 0.707107 0 0" mass="0.2126" diaginertia="0.0003 0.0003 0.0002"/>
                  <joint name="right_elbow_roll_joint" pos="0 0 0" axis="1 0 0" range="-2.97 2.97" actuatorfrcrange="-18.6 18.6" armature="7.302"/>
                  <geom class="visual" mesh="right_elbow_roll_link"/>
                  <body name="right_wrist_pitch_link" pos="0.05345 0 0">
                    <inertial pos="0.0421 0.0042 -0.0038" quat="0.252225 0.608925 0.2878 0.694812" mass="1.2573" diaginertia="0.00293743 0.0029 0.000762572"/>
                    <joint name="right_wrist_pitch_joint" pos="0 0 0" axis="0 1 0" range="-1.57 1.57" actuatorfrcrange="-18.6 18.6" armature="7.302"/>
                    <geom class="visual" mesh="right_wrist_pitch_link"/>
                    <body name="right_wrist_yaw_link" pos="0.085 0 0">
                      <site name="right_hand_mimic" class="mimic" pos="0.1 0.0 0.0"/>
                      <inertial pos="0.0687815 0.0012836 0.00194041" quat="0.531294 0.453341 0.531033 0.479805" mass="0.334" diaginertia="0.0003 0.0004 0.0003"/>
                      <joint name="right_wrist_yaw_joint" pos="0 0 0" axis="0 0 1" range="-1.57 1.57" actuatorfrcrange="-18.6 18.6" armature="7.302"/>
                      <geom class="visual" mesh="right_wrist_yaw_link"/>
                      <!-- Removed hand visuals and collision for right hand to match URDF -->
                      <!-- <geom pos="0.052 0 0" quat="0 0.707107 -0.707107 0" class="visual" mesh="R_hand_base_link"/> -->
                      <!-- <geom name="right_hand_collision" class="collision" type="capsule" size="0.05" fromto="0.05 0 0 0.15 0 0"/> -->
                      <!-- <geom pos="0.1211 0.01696 0.02045" quat="-0.707107 -2.59735e-06 -0.707107 0" class="visual" mesh="Link11_R"/> -->
                      <!-- <geom pos="0.11185 0.027852 0.0292599" quat="0.42452 -0.565494 -0.565493 -0.42452" class="visual" mesh="Link12_R"/> -->
                      <!-- <geom pos="0.146403 0.0393851 0.0718016" quat="0.42452 -0.565494 -0.565493 -0.42452" class="visual" mesh="Link13_R"/> -->
                      <!-- <geom pos="0.156559 0.0438846 0.0915797" quat="0.42452 -0.565494 -0.565493 -0.42452" class="visual" mesh="Link14_R"/> -->
                      <!-- <geom pos="0.18853 -0.00028533 0.032268" quat="0.706999 0.0123358 -0.0123358 -0.706999" class="visual" mesh="Link15_R"/> -->
                      <!-- <geom pos="0.220571 0.00232847 0.0323859" quat="0.706999 0.0123358 -0.0123358 -0.706999" class="visual" mesh="Link16_R"/> -->
                      <!-- <geom pos="0.1891 -0.00028533 0.01295" quat="0.707107 -2.59735e-06 2.59735e-06 -0.707107" class="visual" mesh="Link17_R"/> -->
                      <!-- <geom pos="0.221141 0.00213757 0.0119498" quat="0.707107 -2.59735e-06 2.59735e-06 -0.707107" class="visual" mesh="Link18_R"/> -->
                      <!-- <geom pos="0.18891 -0.00028533 -0.0062872" quat="-0.706864 0.0185215 -0.0185215 0.706864" class="visual" mesh="Link19_R"/> -->
                      <!-- <geom pos="0.220855 0.00213757 -0.00896377" quat="-0.706864 0.0185215 -0.0185215 0.706864" class="visual" mesh="Link20_R"/> -->
                      <!-- <geom pos="0.18771 -0.00028533 -0.025488" quat="-0.706138 0.0369975 -0.0369975 0.706138" class="visual" mesh="Link21_R"/> -->
                      <!-- <geom pos="0.219471 0.00213757 -0.0298309" quat="-0.706138 0.0369975 -0.0369975 0.706138" class="visual" mesh="Link22_R"/> -->
                    </body>
                  </body>
                </body>
              </body>
            </body>
          </body>
        </body>
        <!-- removed head bodies to keep body/DOF at 28/27; merge head mass via torso if needed -->
      </body>
    </body>
  </worldbody>

  <actuator>
    <motor name="left_hip_pitch_joint" joint="left_hip_pitch_joint"  gear="1"/>
    <motor name="left_hip_roll_joint" joint="left_hip_roll_joint" gear="1"/>
    <motor name="left_hip_yaw_joint" joint="left_hip_yaw_joint" gear="1"/>
    <motor name="left_knee_joint" joint="left_knee_joint" gear="1"/>
    <motor name="left_ankle_pitch_joint" joint="left_ankle_pitch_joint" gear="1"/>
    <motor name="left_ankle_roll_joint" joint="left_ankle_roll_joint" gear="1"/>

    <motor name="right_hip_pitch_joint" joint="right_hip_pitch_joint" gear="1"/>
    <motor name="right_hip_roll_joint" joint="right_hip_roll_joint" gear="1"/>
    <motor name="right_hip_yaw_joint" joint="right_hip_yaw_joint" gear="1"/>
    <motor name="right_knee_joint" joint="right_knee_joint" gear="1"/>
    <motor name="right_ankle_pitch_joint" joint="right_ankle_pitch_joint" gear="1"/>
    <motor name="right_ankle_roll_joint" joint="right_ankle_roll_joint" gear="1"/>

    <motor name="waist_yaw_joint" joint="waist_yaw_joint" gear="1"/>

    <motor name="left_shoulder_pitch_joint" joint="left_shoulder_pitch_joint" gear="1"/>
    <motor name="left_shoulder_roll_joint" joint="left_shoulder_roll_joint" gear="1"/>
    <motor name="left_shoulder_yaw_joint" joint="left_shoulder_yaw_joint" gear="1"/>
    <motor name="left_elbow_pitch_joint" joint="left_elbow_pitch_joint" gear="1"/>
    <motor name="left_elbow_roll_joint" joint="left_elbow_roll_joint" gear="1"/>
    <motor name="left_wrist_pitch_joint" joint="left_wrist_pitch_joint" gear="1"/>
    <motor name="left_wrist_yaw_joint" joint="left_wrist_yaw_joint" gear="1"/>


    <motor name="right_shoulder_pitch_joint" joint="right_shoulder_pitch_joint" gear="1"/>
    <motor name="right_shoulder_roll_joint" joint="right_shoulder_roll_joint" gear="1"/>
    <motor name="right_shoulder_yaw_joint" joint="right_shoulder_yaw_joint" gear="1"/>
    <motor name="right_elbow_pitch_joint" joint="right_elbow_pitch_joint" gear="1"/>
    <motor name="right_elbow_roll_joint" joint="right_elbow_roll_joint" gear="1"/>
    <motor name="right_wrist_pitch_joint" joint="right_wrist_pitch_joint" gear="1"/>
    <motor name="right_wrist_yaw_joint" joint="right_wrist_yaw_joint" gear="1"/>



  </actuator>

  <sensor>
    <jointpos name="left_hip_pitch_pos" joint="left_hip_pitch_joint" />
    <jointpos name="left_hip_roll_pos" joint="left_hip_roll_joint" />
    <jointpos name="left_hip_yaw_pos" joint="left_hip_yaw_joint" />
    <jointpos name="left_knee_pos" joint="left_knee_joint" />
    <jointpos name="left_ankle_pitch_pos" joint="left_ankle_pitch_joint" />
    <jointpos name="left_ankle_roll_pos" joint="left_ankle_roll_joint" />

    <jointpos name="right_hip_pitch_pos" joint="right_hip_pitch_joint" />
    <jointpos name="right_hip_roll_pos" joint="right_hip_roll_joint" />
    <jointpos name="right_hip_yaw_pos" joint="right_hip_yaw_joint" />
    <jointpos name="right_knee_pos" joint="right_knee_joint" />
    <jointpos name="right_ankle_pitch_pos" joint="right_ankle_pitch_joint" />
    <jointpos name="right_ankle_roll_pos" joint="right_ankle_roll_joint" />

    <jointpos name="waist_yaw_pos" joint="waist_yaw_joint" />

    <jointpos name="left_shoulder_pitch_pos" joint="left_shoulder_pitch_joint" />
    <jointpos name="left_shoulder_roll_pos" joint="left_shoulder_roll_joint" />
    <jointpos name="left_shoulder_yaw_pos" joint="left_shoulder_yaw_joint" />
    <jointpos name="left_elbow_pos" joint="left_elbow_pitch_joint" />
    <jointpos name="left_elbow_roll_pos" joint="left_elbow_roll_joint" />
    <jointpos name="left_wrist_pitch_pos" joint="left_wrist_pitch_joint" />
    <jointpos name="left_wrist_yaw_pos" joint="left_wrist_yaw_joint" />

    <jointpos name="right_shoulder_pitch_pos" joint="right_shoulder_pitch_joint" />
    <jointpos name="right_shoulder_roll_pos" joint="right_shoulder_roll_joint" />
    <jointpos name="right_shoulder_yaw_pos" joint="right_shoulder_yaw_joint" />
    <jointpos name="right_elbow_pos" joint="right_elbow_pitch_joint" />
    <jointpos name="right_elbow_roll_pos" joint="right_elbow_roll_joint" />
    <jointpos name="right_wrist_pitch_pos" joint="right_wrist_pitch_joint" />
    <jointpos name="right_wrist_yaw_pos" joint="right_wrist_yaw_joint" />




    <jointvel name="left_hip_pitch_vel" joint="left_hip_pitch_joint" />
    <jointvel name="left_hip_roll_vel" joint="left_hip_roll_joint" />
    <jointvel name="left_hip_yaw_vel" joint="left_hip_yaw_joint" />
    <jointvel name="left_knee_vel" joint="left_knee_joint" />
    <jointvel name="left_ankle_pitch_vel" joint="left_ankle_pitch_joint" />
    <jointvel name="left_ankle_roll_vel" joint="left_ankle_roll_joint" />

    <jointvel name="right_hip_pitch_vel" joint="right_hip_pitch_joint" />
    <jointvel name="right_hip_roll_vel" joint="right_hip_roll_joint" />
    <jointvel name="right_hip_yaw_vel" joint="right_hip_yaw_joint" />
    <jointvel name="right_knee_vel" joint="right_knee_joint" />
    <jointvel name="right_ankle_pitch_vel" joint="right_ankle_pitch_joint" />
    <jointvel name="right_ankle_roll_vel" joint="right_ankle_roll_joint" />

    <jointvel name="waist_yaw_vel" joint="waist_yaw_joint" />

    <jointvel name="left_shoulder_pitch_vel" joint="left_shoulder_pitch_joint" />
    <jointvel name="left_shoulder_roll_vel" joint="left_shoulder_roll_joint" />
    <jointvel name="left_shoulder_yaw_vel" joint="left_shoulder_yaw_joint" />
    <jointvel name="left_elbow_vel" joint="left_elbow_pitch_joint" />
    <jointvel name="left_elbow_roll_vel" joint="left_elbow_roll_joint" />
    <jointvel name="left_wrist_pitch_vel" joint="left_wrist_pitch_joint" />
    <jointvel name="left_wrist_yaw_vel" joint="left_wrist_yaw_joint" />
    <jointvel name="right_shoulder_pitch_vel" joint="right_shoulder_pitch_joint" />
    <jointvel name="right_shoulder_roll_vel" joint="right_shoulder_roll_joint" />
    <jointvel name="right_shoulder_yaw_vel" joint="right_shoulder_yaw_joint" />
    <jointvel name="right_elbow_vel" joint="right_elbow_pitch_joint" />
    <jointvel name="right_elbow_roll_vel" joint="right_elbow_roll_joint" />
    <jointvel name="right_wrist_pitch_vel" joint="right_wrist_pitch_joint" />
    <jointvel name="right_wrist_yaw_vel" joint="right_wrist_yaw_joint" />

    <!-- <jointvel name="head_yaw_vel" joint="head_yaw_joint" />
    <jointvel name="head_pitch_vel" joint="right_wrist_yaw_joint" /> -->

    <jointactuatorfrc name="left_hip_pitch_torque" joint="left_hip_pitch_joint" />
    <jointactuatorfrc name="left_hip_roll_torque" joint="left_hip_roll_joint" />
    <jointactuatorfrc name="left_hip_yaw_torque" joint="left_hip_yaw_joint" />
    <jointactuatorfrc name="left_knee_torque" joint="left_knee_joint" />
    <jointactuatorfrc name="left_ankle_pitch_torque" joint="left_ankle_pitch_joint" />
    <jointactuatorfrc name="left_ankle_roll_torque" joint="left_ankle_roll_joint" />
    <jointactuatorfrc name="right_hip_pitch_torque" joint="right_hip_pitch_joint" />
    <jointactuatorfrc name="right_hip_roll_torque" joint="right_hip_roll_joint" />
    <jointactuatorfrc name="right_hip_yaw_torque" joint="right_hip_yaw_joint" />
    <jointactuatorfrc name="right_knee_torque" joint="right_knee_joint" />
    <jointactuatorfrc name="right_ankle_pitch_torque" joint="right_ankle_pitch_joint" />
    <jointactuatorfrc name="right_ankle_roll_torque" joint="right_ankle_roll_joint" />
    <jointactuatorfrc name="waist_yaw_torque" joint="waist_yaw_joint" />
    <jointactuatorfrc name="left_shoulder_pitch_torque" joint="left_shoulder_pitch_joint" />
    <jointactuatorfrc name="left_shoulder_roll_torque" joint="left_shoulder_roll_joint" />
    <jointactuatorfrc name="left_shoulder_yaw_torque" joint="left_shoulder_yaw_joint" />
    <jointactuatorfrc name="left_elbow_torque" joint="left_elbow_pitch_joint" />
    <jointactuatorfrc name="left_elbow_roll_torque" joint="left_elbow_roll_joint" />
    <jointactuatorfrc name="left_wrist_pitch_torque" joint="left_wrist_pitch_joint" />
    <jointactuatorfrc name="left_wrist_yaw_torque" joint="left_wrist_yaw_joint" />
    <jointactuatorfrc name="right_shoulder_pitch_torque" joint="right_shoulder_pitch_joint" />
    <jointactuatorfrc name="right_shoulder_roll_torque" joint="right_shoulder_roll_joint" />
    <jointactuatorfrc name="right_shoulder_yaw_torque" joint="right_shoulder_yaw_joint" />
    <jointactuatorfrc name="right_elbow_torque" joint="right_elbow_pitch_joint" />
    <jointactuatorfrc name="right_elbow_roll_torque" joint="right_elbow_roll_joint" />
    <jointactuatorfrc name="right_wrist_pitch_torque" joint="right_wrist_pitch_joint" />
    <jointactuatorfrc name="right_wrist_yaw_torque" joint="right_wrist_yaw_joint" />

    <!-- <jointactuatorfrc name="head_yaw_torque" joint="head_yaw_joint" />
    <jointactuatorfrc name="head_pitch_torque" joint="right_wrist_yaw_joint" /> -->

    <framequat name="imu_quat" objtype="site" objname="imu_in_pelvis" />
    <gyro name="imu-pelvis-angular-velocity" site="imu_in_pelvis" noise="5e-4" cutoff="34.9"/>
    <accelerometer name="imu-pelvis-linear-acceleration" site="imu_in_pelvis" noise="1e-2" cutoff="157"/>

    <framepos name="frame_pos" objtype="site" objname="imu_in_pelvis" />
    <framelinvel name="frame_vel" objtype="site" objname="imu_in_pelvis" />
  </sensor>


  <!-- setup scene -->
  <statistic center="1.0 0.7 1.0" extent="0.8"/>
  <visual>
    <headlight diffuse="0.6 0.6 0.6" ambient="0.3 0.3 0.3" specular="0 0 0"/>
    <rgba haze="0.871 0.616 0.4 0.5"/>
    <global azimuth="-130" elevation="-20"/>
  </visual>
  <asset>
      <texture builtin="gradient" height="100" rgb1="0.9 0.9 0.9" rgb2="0.549 0.251 0.0" type="skybox" width="100"/>
      <texture name="texplane" type="2d" builtin="checker" rgb1="0.5 0.5 0.5" rgb2="0.55 0.55 0.55" width="100" height="100"/>
      <material name="MatPlane" reflectance="0.0" texture="texplane" texrepeat="1 1" texuniform="true"/>
  </asset>
  <worldbody>
      <geom name="floor" friction="1 .1 .1" pos="0 0 0" size="0 0 0.125" type="plane" material="MatPlane" condim="3" conaffinity="1" contype="1" group="2" rgba="0.8 0.9 0.8 1"/>
      <light cutoff="1000" diffuse="1.5 1.5 1.5" dir="-0 0 -1.3" directional="true" exponent="10" pos="0 0 10.3" specular=".1 .1 .1" castshadow="false"/>
  </worldbody>

</mujoco>