<mujoco model="P3-atom-251117-2">
  <compiler angle="radian" meshdir="meshes/"/>

  <size njmax="500" nconmax="100" />
  <default>
    <!-- <joint damping="0.001" armature="0.01" frictionloss="0.1"/> -->
    <joint actuatorfrclimited="true"  armature="0.01" frictionloss="0.1" damping="0.001"/>


    <default class="visual">
      <geom type="mesh" contype="0" conaffinity="0" group="0" density="0" rgba="0.69804 0.69804 0.69804 1"/>
    </default>

    <default class="collision">
        <geom group="3" rgba=".2 .6 .2 .3" contype="1" conaffinity="1"/>
    </default>

  </default>

  <asset>
    <mesh name="pelvis" content_type="model/stl" file="pelvis.STL"/>
    <mesh name="left_hip_pitch_link" content_type="model/stl" file="left_hip_pitch_link.STL"/>
    <mesh name="left_hip_roll_link" content_type="model/stl" file="left_hip_roll_link.STL"/>
    <mesh name="left_hip_yaw_link" content_type="model/stl" file="left_hip_yaw_link.STL"/>
    <mesh name="left_knee_link" content_type="model/stl" file="left_knee_link.STL"/>
    <mesh name="left_ankle_pitch_link" content_type="model/stl" file="left_ankle_pitch_link.STL"/>
    <mesh name="left_ankle_roll_link" content_type="model/stl" file="left_ankle_roll_link.STL"/>
    <mesh name="right_hip_pitch_link" content_type="model/stl" file="right_hip_pitch_link.STL"/>
    <mesh name="right_hip_roll_link" content_type="model/stl" file="right_hip_roll_link.STL"/>
    <mesh name="right_hip_yaw_link" content_type="model/stl" file="right_hip_yaw_link.STL"/>
    <mesh name="right_knee_link" content_type="model/stl" file="right_knee_link.STL"/>
    <mesh name="right_ankle_pitch_link" content_type="model/stl" file="right_ankle_pitch_link.STL"/>
    <mesh name="right_ankle_roll_link" content_type="model/stl" file="right_ankle_roll_link.STL"/>
    <mesh name="torso_link" content_type="model/stl" file="torso_link.STL"/>
    <mesh name="head_yaw_link" content_type="model/stl" file="head_yaw_link.STL"/>
    <mesh name="head_pitch_link" content_type="model/stl" file="head_pitch_link.STL"/>
    <mesh name="left_shoulder_pitch_Link" content_type="model/stl" file="left_shoulder_pitch_Link.STL"/>
    <mesh name="left_shoulder_roll_Link" content_type="model/stl" file="left_shoulder_roll_Link.STL"/>
    <mesh name="left_shoulder_yaw_Link" content_type="model/stl" file="left_shoulder_yaw_Link.STL"/>
    <mesh name="left_elbow_pitch_Link" content_type="model/stl" file="left_elbow_pitch_Link.STL"/>
    <mesh name="left_elbow_roll_Link" content_type="model/stl" file="left_elbow_roll_Link.STL"/>
    <mesh name="left_wrist_pitch_Link" content_type="model/stl" file="left_wrist_pitch_Link.STL"/>
    <mesh name="left_wrist_yaw_Link" content_type="model/stl" file="left_wrist_yaw_Link.STL"/>
    <mesh name="right_shoulder_pitch_Link" content_type="model/stl" file="right_shoulder_pitch_Link.STL"/>
    <mesh name="right_shoulder_roll_Link" content_type="model/stl" file="right_shoulder_roll_Link.STL"/>
    <mesh name="right_shoulder_yaw_Link" content_type="model/stl" file="right_shoulder_yaw_Link.STL"/>
    <mesh name="right_elbow_pitch_Link" content_type="model/stl" file="right_elbow_pitch_Link.STL"/>
    <mesh name="right_elbow_roll_Link" content_type="model/stl" file="right_elbow_roll_Link.STL"/>
    <mesh name="right_wrist_pitch_Link" content_type="model/stl" file="right_wrist_pitch_Link.STL"/>
    <mesh name="right_wrist_yaw_Link" content_type="model/stl" file="right_wrist_yaw_Link.STL"/>
  </asset>

  <worldbody>
    <body name="pelvis" pos="0 0 0.98">
      <inertial pos="0 0 -0.10137" quat="0.999993 0.000433435 -0.00354764 0.000586863" mass="6.9199" diaginertia="0.0363439 0.0307156 0.0228589"/>
      <joint name="floating_base_joint" type="free"/>
      <geom class="visual" mesh="pelvis"/>
      <geom name="pelvis_collision" class="collision" type="sphere" size="0.085" pos="0 0 -0.12"/>
      <site name="imu_in_pelvis" size="0.01" pos="0.0 0.0 -0.18"/>

      <body name="left_hip_pitch_link" pos="0 0.078 -0.133">
        <inertial pos="0.014483 0.033287 -0.004616" quat="0.0178309 0.634158 0.524081 0.568212" mass="0.5122" diaginertia="0.00120307 0.00110098 0.000610593"/>
        <joint name="left_hip_pitch_joint" pos="0 0 0" axis="0 1 0" range="-2.5656 3.0194" actuatorfrcrange="-207.76 207.76" armature="0.10897986"/>
        <geom class="visual" mesh="left_hip_pitch_link"/>
        <body name="left_hip_roll_link" pos="0.042821 0.0735 -0.020283" quat="0.998392 0 -0.0566946 0">
          <inertial pos="-0.0466517 -0.00050804 -0.00836534" quat="0.595141 -0.14232 0.123345 0.781242" mass="2.408" diaginertia="0.00392468 0.00386766 0.00327811"/>
          <joint name="left_hip_roll_joint" pos="0 0 0" axis="1 0 0" range="-0.2618 1.6581" actuatorfrcrange="-241.42 241.42" armature="0.070622376"/>
          <geom class="visual" mesh="left_hip_roll_link"/>
          <geom name="left_thigh" class="collision" size="0.065 0.175" pos="-0.05 0 -0.15" quat="0.998392 0 0.0566928 0" type="cylinder"/>

          <body name="left_hip_yaw_link" pos="-0.048 -0.020002 -0.0655">
            <inertial pos="-0.00286469 0.013368 -0.117369" quat="0.613318 0.0572686 -0.0192347 0.787522" mass="5.8156" diaginertia="0.0431012 0.0417621 0.0132598"/>
            <joint name="left_hip_yaw_joint" pos="0 0 0" axis="0 0 1" range="-2.7925 2.7925" actuatorfrcrange="-104.16 104.16" armature="0.036700268"/>
            <geom class="visual" mesh="left_hip_yaw_link"/>
            <body name="left_knee_link" pos="-0.046862 0 -0.32295" quat="0.998392 0 0.0566946 0">
              <inertial pos="0.00233969 0 -0.113041" quat="0.879773 -0.0101892 -0.0264678 0.474548" mass="3.41601" diaginertia="0.0261893 0.0260194 0.0036881"/>
              <joint name="left_knee_joint" pos="0 0 0" axis="0 1 0" range="0 2.4434" actuatorfrcrange="-213.8 213.8" armature="0.0812586105"/>
              <geom class="visual" mesh="left_knee_link"/>
              <geom name="left_shin" class="collision" size="0.06 0.15" pos="0 0 -0.16" type="cylinder"/>

              <body name="left_ankle_pitch_link" pos="0.006 0 -0.335">
                <inertial pos="0 0 -0.0119444" mass="0.115403" diaginertia="3.014e-05 2.5e-05 1.7e-05"/>
                <joint name="left_ankle_pitch_joint" pos="0 0 0" axis="0 1 0" range="-0.8727 0.5236" actuatorfrcrange="-89.896 89.896" armature="0.01536"/>
                <geom class="visual" mesh="left_ankle_pitch_link"/>
                <body name="left_ankle_roll_link" pos="0 0 -0.025">
                  <inertial pos="0.0298504 0 -0.0333895" quat="0 0.707107 0 0.707107" mass="0.731286" diaginertia="0.00337907 0.00331246 0.00072777"/>
                  <joint name="left_ankle_roll_joint" pos="0 0 0" axis="1 0 0" range="-0.48 0.48" actuatorfrcrange="-89.896 89.896" armature="0.01536"/>
                  <geom class="visual" mesh="left_ankle_roll_link"/>
                  <geom name="left_foot_collision" class="collision" size="0.12 0.04 0.01" pos="0.036 0 -0.056" type="box" />
                </body>
              </body>
            </body>
          </body>
        </body>
      </body>
      <body name="right_hip_pitch_link" pos="0 -0.078 -0.133">
        <inertial pos="0.0144827 -0.0332865 -0.00461615" quat="-0.0178309 0.634158 -0.524081 0.568212" mass="0.5122" diaginertia="0.00120307 0.00110098 0.000610593"/>
        <joint name="right_hip_pitch_joint" pos="0 0 0" axis="0 1 0" range="-2.5656 3.0194" actuatorfrcrange="-207.76 207.76" armature="0.10897986"/>
        <geom class="visual" mesh="right_hip_pitch_link"/>
        <body name="right_hip_roll_link" pos="0.042821 -0.0735 -0.020283" quat="0.998392 0 -0.0566946 0">
          <inertial pos="-0.0462933 0.00050804 -0.00816099" quat="0.781242 0.123345 -0.14232 0.595141" mass="2.40797" diaginertia="0.00392468 0.00386766 0.00327811"/>
          <joint name="right_hip_roll_joint" pos="0 0 0" axis="1 0 0" range="-1.6581 0.2618" actuatorfrcrange="-241.42 241.42" armature="0.070622376"/>
          <geom class="visual" mesh="right_hip_roll_link"/>
          <geom name="right_thigh" class="collision"  size="0.065 0.175" pos="-0.05 0 -0.15" quat="0.998392 0 0.0566928 0" type="cylinder" />
          <body name="right_hip_yaw_link" pos="-0.048 0.020002 -0.0655" quat="1 0 0 -2.16435e-05">
            <inertial pos="-0.00286469 -0.013368 -0.117369" quat="0.787522 -0.0192347 0.0572686 0.613318" mass="5.8156" diaginertia="0.0431012 0.0417621 0.0132598"/>
            <joint name="right_hip_yaw_joint" pos="0 0 0" axis="0 0 1" range="-2.7925 2.7925" actuatorfrcrange="-104.16 104.16" armature="0.036700268"/>
            <geom class="visual" mesh="right_hip_yaw_link"/>
            <body name="right_knee_link" pos="-0.046862 0 -0.32295" quat="0.998392 0 0.0566946 0">
              <inertial pos="0.00233969 0 -0.113041" quat="0.474562 -0.0264657 -0.0101886 0.879765" mass="3.41565" diaginertia="0.0261893 0.0260194 0.00368811"/>
              <joint name="right_knee_joint" pos="0 0 0" axis="0 1 0" range="0 2.4434" actuatorfrcrange="-213.8 213.8" armature="0.0812586105"/>
              <geom class="visual" mesh="right_knee_link"/>
              <geom name="right_shin" class="collision" size="0.06 0.15" pos="0 0 -0.16" type="cylinder" />

              <body name="right_ankle_pitch_link" pos="0.006 0 -0.335">
                <inertial pos="0 0 -0.0119444" mass="0.115403" diaginertia="3.014e-05 2.5e-05 1.7e-05"/>
                <joint name="right_ankle_pitch_joint" pos="0 0 0" axis="0 1 0" range="-0.8727 0.5236" actuatorfrcrange="-89.896 89.896" armature="0.01536"/>
                <geom class="visual" mesh="right_ankle_pitch_link"/>
                <body name="right_ankle_roll_link" pos="0 0 -0.025">
                  <inertial pos="0.02985 0 -0.03339" quat="0 0.707107 0 0.707107" mass="0.731286" diaginertia="0.00337907 0.00331246 0.00072777"/>
                  <joint name="right_ankle_roll_joint" pos="0 0 0" axis="1 0 0" range="-0.48 0.48" actuatorfrcrange="-89.896 89.896" armature="0.01536"/>
                  <geom class="visual" mesh="right_ankle_roll_link"/>
                  <geom name="right_foot_collision" class="collision" size="0.12 0.04 0.01" pos="0.036 0 -0.056" type="box" />
                </body>
              </body>
            </body>
          </body>
        </body>
      </body>
      <body name="torso_link">
        <inertial pos="-0.00433769 2.06404e-06 0.214769" quat="0.999994 2.09002e-05 0.0033223 1.52381e-05" mass="15.2508" diaginertia="0.23486 0.182911 0.0759382"/>
        <joint name="torso_joint" pos="0 0 0" axis="0 0 1" range="-2.97 2.97" actuatorfrcrange="-182.28 182.28" armature="0.1123945708"/>
        <geom class="visual" mesh="torso_link"/>
        <geom name="torso_collision" class="collision"  size="0.11 0.12 0.2" pos="0 0 0.2" type="box" />
        <body name="head_yaw_link" pos="0 0 0.4027">
          <inertial pos="0 0 0.038542" mass="0.411938" diaginertia="0.000246815 0.000220591 0.000216563"/>
<!--          <joint name="head_yaw_joint" pos="0 0 0" axis="0 0 1" range="-1.57 1.57" actuatorfrcrange="-12 12" armature="0.0063"/>-->
          <geom class="visual" mesh="head_yaw_link"/>
          <body name="head_pitch_link" pos="0 0 0.041">
            <inertial pos="0.0282309 4.09627e-06 0.127179" quat="0.706956 0.0141451 0.0141447 0.706975" mass="1.47566" diaginertia="0.00762241 0.00695772 0.00480094"/>
<!--            <joint name="head_pitch_joint" pos="0 0 0" axis="0 1 0" range="-0.87 0.61" actuatorfrcrange="-12 12" armature="0.0063"/>-->
            <geom class="visual" mesh="head_pitch_link"/>
          </body>
        </body>



        <body name="left_shoulder_pitch_Link" pos="0 0.1315 0.333">
          <inertial pos="0.0044 0.0368 0" quat="0.0878415 0.57587 -0.237641 0.777293" mass="0.4473" diaginertia="0.00103429 0.000847068 0.000618639"/>
          <joint name="left_shoulder_pitch_joint" pos="0 0 0" axis="0 1 0" range="-2.97 2.97" actuatorfrcrange="-93 93" armature="0.624"/>
          <geom class="visual" mesh="left_shoulder_pitch_Link"/>
          <body name="left_shoulder_roll_Link" pos="0 0.0745 0">
            <inertial pos="0.0124 0.0009 -0.0545" quat="0.706611 -0.0264772 -0.0264772 0.706611" mass="1.794" diaginertia="0.0067 0.00663002 0.00126998"/>
            <joint name="left_shoulder_roll_joint" pos="0 0 0" axis="1 0 0" range="-0.43 3.14" actuatorfrcrange="-70 70" armature="0.24"/>
            <geom class="visual" mesh="left_shoulder_roll_Link"/>
            <body name="left_shoulder_yaw_Link" pos="0 0 -0.134" quat="1 -1.0521e-05 0 0">
              <inertial pos="-0.0014 0.0066 -0.1179" quat="0.996622 -0.0589197 0.050134 0.0275679" mass="0.9798" diaginertia="0.00181039 0.00161157 0.000778049"/>
              <joint name="left_shoulder_yaw_joint" pos="0 0 0" axis="0 0 1" range="-2.97 2.97" actuatorfrcrange="-70 70" armature="0.24"/>
              <geom class="visual" mesh="left_shoulder_yaw_Link"/>
              <geom name="left_shoulder_yaw_collision" class="collision" size="0.038 0.12" pos="0 0 0.04" quat="-3.67321e-06 1 0 0" type="cylinder" />
              <body name="left_elbow_pitch_Link" pos="0 0 -0.131">
                <inertial pos="0.0903 0.0016 -0.0003" quat="-0.0206991 0.706804 0.0206991 0.706804" mass="0.8548" diaginertia="0.0028 0.00250586 0.000794138"/>
                <joint name="left_elbow_pitch_joint" pos="0 0 0" axis="0 1 0" range="-0.87 3.14" actuatorfrcrange="-70 70" armature="0.24"/>
                <geom class="visual" mesh="left_elbow_pitch_Link"/>
                <geom name="left_elbow_pitch_collision" class="collision" size="0.038 0.075" pos="0.15 0 0" quat="0.707105 0 -0.707108 0" type="cylinder" />
                <body name="left_elbow_roll_Link" pos="0.1453 0 0">
                  <inertial pos="0.027 0.0018 -0.0002" quat="0.707107 0.707107 0 0" mass="0.2126" diaginertia="0.0003 0.0003 0.0002"/>
                  <joint name="left_elbow_roll_joint" pos="0 0 0" axis="1 0 0" range="-2.97 2.97" actuatorfrcrange="-34 34" armature="0.073"/>
                  <geom class="visual" mesh="left_elbow_roll_Link"/>
                  <body name="left_wrist_pitch_Link" pos="0.05345 0 0">
                    <inertial pos="0.0421 -0.0042 -0.0038" quat="-0.252225 0.608925 -0.2878 0.694812" mass="1.2573" diaginertia="0.00293743 0.0029 0.000762572"/>
                    <joint name="left_wrist_pitch_joint" pos="0 0 0" axis="0 1 0" range="-1.57 1.57" actuatorfrcrange="-34 34" armature="0.073"/>
                    <geom class="visual" mesh="left_wrist_pitch_Link"/>
                    <body name="left_wrist_yaw_Link" pos="0.085 0 0">
                      <inertial pos="0.029 0.0004 0.001" quat="0.707107 0 0 0.707107" mass="0.334" diaginertia="0.0004 0.0003 0.0003"/>
                      <joint name="left_wrist_yaw_joint" pos="0 0 0" axis="0 0 1" range="-1.57 1.57" actuatorfrcrange="-34 34" armature="0.073"/>
                      <geom class="visual" mesh="left_wrist_yaw_Link"/>
                      <geom name="left_wrist_yaw_collision" class="collision" size="0.05" pos="0.02 0 0" />
                    </body>
                  </body>
                </body>
              </body>
            </body>
          </body>
        </body>
        <body name="right_shoulder_pitch_Link" pos="0 -0.1315 0.333">
          <inertial pos="0.0044 -0.0368 0" quat="-0.0878415 0.57587 0.237641 0.777293" mass="0.4473" diaginertia="0.00103429 0.000847068 0.000618639"/>
          <joint name="right_shoulder_pitch_joint" pos="0 0 0" axis="0 1 0" range="-2.97 2.97" actuatorfrcrange="-93 93"/>
          <geom class="visual" mesh="right_shoulder_pitch_Link"/>
          <body name="right_shoulder_roll_Link" pos="0 -0.0745 0">
            <inertial pos="0.0124 -0.0009 -0.0545" quat="0.706611 -0.0264772 -0.0264772 0.706611" mass="1.794" diaginertia="0.0067 0.00663002 0.00126998"/>
            <joint name="right_shoulder_roll_joint" pos="0 0 0" axis="1 0 0" range="-3.14 0.43" actuatorfrcrange="-70 70"/>
            <geom class="visual" mesh="right_shoulder_roll_Link"/>
            <body name="right_shoulder_yaw_Link" pos="0 0 -0.134" quat="1 1.0521e-05 0 0">
              <inertial pos="-0.0014 -0.0066 -0.1179" quat="0.996622 0.0589197 0.050134 -0.0275679" mass="0.9798" diaginertia="0.00181039 0.00161157 0.000778049"/>
              <joint name="right_shoulder_yaw_joint" pos="0 0 0" axis="0 0 1" range="-2.97 2.97" actuatorfrcrange="-70 70"/>
              <geom class="visual" mesh="right_shoulder_yaw_Link"/>
              <geom name="right_shoulder_yaw_collision" class="collision" size="0.038 0.12" pos="0 0 0.04" quat="-3.67321e-06 1 0 0" type="cylinder" />
              <body name="right_elbow_pitch_Link" pos="0 0 -0.131">
                <inertial pos="0.0903 -0.0016 -0.0003" quat="0.0206991 0.706804 -0.0206991 0.706804" mass="0.8548" diaginertia="0.0028 0.00250586 0.000794138"/>
                <joint name="right_elbow_pitch_joint" pos="0 0 0" axis="0 1 0" range="-0.87 3.14" actuatorfrcrange="-70 70"/>
                <geom class="visual" mesh="right_elbow_pitch_Link"/>
                <geom name="right_elbow_pitch_collision" class="collision" size="0.038 0.075" pos="0.15 0 0" quat="0.707105 0 -0.707108 0" type="cylinder" />
                <body name="right_elbow_roll_Link" pos="0.1453 0 0">
                  <inertial pos="0.027 -0.0018 -0.0002" quat="0.707107 0.707107 0 0" mass="0.2126" diaginertia="0.0003 0.0003 0.0002"/>
                  <joint name="right_elbow_roll_joint" pos="0 0 0" axis="1 0 0" range="-2.97 2.97" actuatorfrcrange="-34 34"/>
                  <geom class="visual" mesh="right_elbow_roll_Link"/>
                  <body name="right_wrist_pitch_Link" pos="0.05345 0 0">
                    <inertial pos="0.0421 0.0042 -0.0038" quat="0.252225 0.608925 0.2878 0.694812" mass="1.2573" diaginertia="0.00293743 0.0029 0.000762572"/>
                    <joint name="right_wrist_pitch_joint" pos="0 0 0" axis="0 1 0" range="-1.57 1.57" actuatorfrcrange="-34 34"/>
                    <geom class="visual" mesh="right_wrist_pitch_Link"/>
                    <body name="right_wrist_yaw_Link" pos="0.085 0 0">
                      <inertial pos="0.029 -0.0004 0.001" quat="0.707107 0 0 0.707107" mass="0.334" diaginertia="0.0004 0.0003 0.0003"/>
                      <joint name="right_wrist_yaw_joint" pos="0 0 0" axis="0 0 1" range="-1.57 1.57" actuatorfrcrange="-34 34"/>
                      <geom class="visual" mesh="right_wrist_yaw_Link"/>
                      <geom name="right_wrist_yaw_collision" class="collision" size="0.05" pos="0.02 0 0" />
                    </body>
                  </body>
                </body>
              </body>
            </body>
          </body>
        </body>
      </body>
    </body>
  </worldbody>

  <actuator>
    <motor name="left_hip_pitch_joint" joint="left_hip_pitch_joint"  gear="1"/>
    <motor name="left_hip_roll_joint" joint="left_hip_roll_joint" gear="1"/>
    <motor name="left_hip_yaw_joint" joint="left_hip_yaw_joint" gear="1"/>
    <motor name="left_knee_joint" joint="left_knee_joint" gear="1"/>
    <motor name="left_ankle_pitch_joint" joint="left_ankle_pitch_joint" gear="1"/>
    <motor name="left_ankle_roll_joint" joint="left_ankle_roll_joint" gear="1"/>

    <motor name="right_hip_pitch_joint" joint="right_hip_pitch_joint" gear="1"/>
    <motor name="right_hip_roll_joint" joint="right_hip_roll_joint" gear="1"/>
    <motor name="right_hip_yaw_joint" joint="right_hip_yaw_joint" gear="1"/>
    <motor name="right_knee_joint" joint="right_knee_joint" gear="1"/>
    <motor name="right_ankle_pitch_joint" joint="right_ankle_pitch_joint" gear="1"/>
    <motor name="right_ankle_roll_joint" joint="right_ankle_roll_joint" gear="1"/>

    <motor name="torso_joint" joint="torso_joint" gear="1"/>

    <motor name="left_shoulder_pitch_joint" joint="left_shoulder_pitch_joint" gear="1"/>
    <motor name="left_shoulder_roll_joint" joint="left_shoulder_roll_joint" gear="1"/>
    <motor name="left_shoulder_yaw_joint" joint="left_shoulder_yaw_joint" gear="1"/>
    <motor name="left_elbow_pitch_joint" joint="left_elbow_pitch_joint" gear="1"/>
    <motor name="left_elbow_roll_joint" joint="left_elbow_roll_joint" gear="1"/>
    <motor name="left_wrist_pitch_joint" joint="left_wrist_pitch_joint" gear="1"/>
    <motor name="left_wrist_yaw_joint" joint="left_wrist_yaw_joint" gear="1"/>


    <motor name="right_shoulder_pitch_joint" joint="right_shoulder_pitch_joint" gear="1"/>
    <motor name="right_shoulder_roll_joint" joint="right_shoulder_roll_joint" gear="1"/>
    <motor name="right_shoulder_yaw_joint" joint="right_shoulder_yaw_joint" gear="1"/>
    <motor name="right_elbow_pitch_joint" joint="right_elbow_pitch_joint" gear="1"/>
    <motor name="right_elbow_roll_joint" joint="right_elbow_roll_joint" gear="1"/>
    <motor name="right_wrist_pitch_joint" joint="right_wrist_pitch_joint" gear="1"/>
    <motor name="right_wrist_yaw_joint" joint="right_wrist_yaw_joint" gear="1"/>


    <!--<motor name="head_yaw_joint" joint="head_yaw_joint"  gear="1"/>-->
    <!--<motor name="head_pitch_joint" joint="head_pitch_joint" gear="1"/>-->

  </actuator>



  <sensor>
    <jointpos name="left_hip_pitch_pos" joint="left_hip_pitch_joint" />
    <jointpos name="left_hip_roll_pos" joint="left_hip_roll_joint" />
    <jointpos name="left_hip_yaw_pos" joint="left_hip_yaw_joint" />
    <jointpos name="left_knee_pos" joint="left_knee_joint" />
    <jointpos name="left_ankle_pitch_pos" joint="left_ankle_pitch_joint" />
    <jointpos name="left_ankle_roll_pos" joint="left_ankle_roll_joint" />

    <jointpos name="right_hip_pitch_pos" joint="right_hip_pitch_joint" />
    <jointpos name="right_hip_roll_pos" joint="right_hip_roll_joint" />
    <jointpos name="right_hip_yaw_pos" joint="right_hip_yaw_joint" />
    <jointpos name="right_knee_pos" joint="right_knee_joint" />
    <jointpos name="right_ankle_pitch_pos" joint="right_ankle_pitch_joint" />
    <jointpos name="right_ankle_roll_pos" joint="right_ankle_roll_joint" />

    <jointpos name="waist_yaw_pos" joint="torso_joint" />

    <jointpos name="left_shoulder_pitch_pos" joint="left_shoulder_pitch_joint" />
    <jointpos name="left_shoulder_roll_pos" joint="left_shoulder_roll_joint" />
    <jointpos name="left_shoulder_yaw_pos" joint="left_shoulder_yaw_joint" />
    <jointpos name="left_elbow_pos" joint="left_elbow_pitch_joint" />
    <jointpos name="left_elbow_roll_pos" joint="left_elbow_roll_joint" />
    <jointpos name="left_wrist_pitch_pos" joint="left_wrist_pitch_joint" />
    <jointpos name="left_wrist_yaw_pos" joint="left_wrist_yaw_joint" />

    <jointpos name="right_shoulder_pitch_pos" joint="right_shoulder_pitch_joint" />
    <jointpos name="right_shoulder_roll_pos" joint="right_shoulder_roll_joint" />
    <jointpos name="right_shoulder_yaw_pos" joint="right_shoulder_yaw_joint" />
    <jointpos name="right_elbow_pos" joint="right_elbow_pitch_joint" />
    <jointpos name="right_elbow_roll_pos" joint="right_elbow_roll_joint" />
    <jointpos name="right_wrist_pitch_pos" joint="right_wrist_pitch_joint" />
    <jointpos name="right_wrist_yaw_pos" joint="right_wrist_yaw_joint" />

<!--    <jointpos name="head_yaw__pos" joint="head_yaw_joint" />-->
<!--    <jointpos name="head_pitch_pos" joint="head_pitch_joint" />-->


    <jointvel name="left_hip_pitch_vel" joint="left_hip_pitch_joint" />
    <jointvel name="left_hip_roll_vel" joint="left_hip_roll_joint" />
    <jointvel name="left_hip_yaw_vel" joint="left_hip_yaw_joint" />
    <jointvel name="left_knee_vel" joint="left_knee_joint" />
    <jointvel name="left_ankle_pitch_vel" joint="left_ankle_pitch_joint" />
    <jointvel name="left_ankle_roll_vel" joint="left_ankle_roll_joint" />

    <jointvel name="right_hip_pitch_vel" joint="right_hip_pitch_joint" />
    <jointvel name="right_hip_roll_vel" joint="right_hip_roll_joint" />
    <jointvel name="right_hip_yaw_vel" joint="right_hip_yaw_joint" />
    <jointvel name="right_knee_vel" joint="right_knee_joint" />
    <jointvel name="right_ankle_pitch_vel" joint="right_ankle_pitch_joint" />
    <jointvel name="right_ankle_roll_vel" joint="right_ankle_roll_joint" />

    <jointvel name="waist_yaw_vel" joint="torso_joint" />

    <jointvel name="left_shoulder_pitch_vel" joint="left_shoulder_pitch_joint" />
    <jointvel name="left_shoulder_roll_vel" joint="left_shoulder_roll_joint" />
    <jointvel name="left_shoulder_yaw_vel" joint="left_shoulder_yaw_joint" />
    <jointvel name="left_elbow_vel" joint="left_elbow_pitch_joint" />
    <jointvel name="left_elbow_roll_vel" joint="left_elbow_roll_joint" />
    <jointvel name="left_wrist_pitch_vel" joint="left_wrist_pitch_joint" />
    <jointvel name="left_wrist_yaw_vel" joint="left_wrist_yaw_joint" />
    <jointvel name="right_shoulder_pitch_vel" joint="right_shoulder_pitch_joint" />
    <jointvel name="right_shoulder_roll_vel" joint="right_shoulder_roll_joint" />
    <jointvel name="right_shoulder_yaw_vel" joint="right_shoulder_yaw_joint" />
    <jointvel name="right_elbow_vel" joint="right_elbow_pitch_joint" />
    <jointvel name="right_elbow_roll_vel" joint="right_elbow_roll_joint" />
    <jointvel name="right_wrist_pitch_vel" joint="right_wrist_pitch_joint" />
    <jointvel name="right_wrist_yaw_vel" joint="right_wrist_yaw_joint" />

<!--    <jointvel name="head_yaw_vel" joint="head_yaw_joint" />-->
<!--    <jointvel name="head_pitch_vel" joint="head_pitch_joint" />-->

    <jointactuatorfrc name="left_hip_pitch_torque" joint="left_hip_pitch_joint" />
    <jointactuatorfrc name="left_hip_roll_torque" joint="left_hip_roll_joint" />
    <jointactuatorfrc name="left_hip_yaw_torque" joint="left_hip_yaw_joint" />
    <jointactuatorfrc name="left_knee_torque" joint="left_knee_joint" />
    <jointactuatorfrc name="left_ankle_pitch_torque" joint="left_ankle_pitch_joint" />
    <jointactuatorfrc name="left_ankle_roll_torque" joint="left_ankle_roll_joint" />
    <jointactuatorfrc name="right_hip_pitch_torque" joint="right_hip_pitch_joint" />
    <jointactuatorfrc name="right_hip_roll_torque" joint="right_hip_roll_joint" />
    <jointactuatorfrc name="right_hip_yaw_torque" joint="right_hip_yaw_joint" />
    <jointactuatorfrc name="right_knee_torque" joint="right_knee_joint" />
    <jointactuatorfrc name="right_ankle_pitch_torque" joint="right_ankle_pitch_joint" />
    <jointactuatorfrc name="right_ankle_roll_torque" joint="right_ankle_roll_joint" />
    <jointactuatorfrc name="waist_yaw_torque" joint="torso_joint" />
    <jointactuatorfrc name="left_shoulder_pitch_torque" joint="left_shoulder_pitch_joint" />
    <jointactuatorfrc name="left_shoulder_roll_torque" joint="left_shoulder_roll_joint" />
    <jointactuatorfrc name="left_shoulder_yaw_torque" joint="left_shoulder_yaw_joint" />
    <jointactuatorfrc name="left_elbow_torque" joint="left_elbow_pitch_joint" />
    <jointactuatorfrc name="left_elbow_roll_torque" joint="left_elbow_roll_joint" />
    <jointactuatorfrc name="left_wrist_pitch_torque" joint="left_wrist_pitch_joint" />
    <jointactuatorfrc name="left_wrist_yaw_torque" joint="left_wrist_yaw_joint" />
    <jointactuatorfrc name="right_shoulder_pitch_torque" joint="right_shoulder_pitch_joint" />
    <jointactuatorfrc name="right_shoulder_roll_torque" joint="right_shoulder_roll_joint" />
    <jointactuatorfrc name="right_shoulder_yaw_torque" joint="right_shoulder_yaw_joint" />
    <jointactuatorfrc name="right_elbow_torque" joint="right_elbow_pitch_joint" />
    <jointactuatorfrc name="right_elbow_roll_torque" joint="right_elbow_roll_joint" />
    <jointactuatorfrc name="right_wrist_pitch_torque" joint="right_wrist_pitch_joint" />
    <jointactuatorfrc name="right_wrist_yaw_torque" joint="right_wrist_yaw_joint" />

<!--    <jointactuatorfrc name="head_yaw_torque" joint="head_yaw_joint" />-->
<!--    <jointactuatorfrc name="head_pitch_torque" joint="head_pitch_joint" />-->

    <framequat name="imu_quat" objtype="site" objname="imu_in_pelvis" />
    <gyro name="imu-pelvis-angular-velocity" site="imu_in_pelvis" noise="5e-4" cutoff="34.9"/>
    <accelerometer name="imu-pelvis-linear-acceleration" site="imu_in_pelvis" noise="1e-2" cutoff="157"/>

    <framepos name="frame_pos" objtype="site" objname="imu_in_pelvis" />
    <velocimeter name="frame_local_vel" site="imu_in_pelvis" />
  </sensor>


  <!-- setup scene -->
  <statistic center="1.0 0.7 1.0" extent="0.8"/>
  <visual>
    <headlight diffuse="0.6 0.6 0.6" ambient="0.3 0.3 0.3" specular="0 0 0"/>
    <rgba haze="0.871 0.616 0.4 0.5"/>
    <global azimuth="-130" elevation="-20"/>
  </visual>
  <asset>
      <texture builtin="gradient" height="100" rgb1="0.9 0.9 0.9" rgb2="0.549 0.251 0.0" type="skybox" width="100"/>
      <texture name="texplane" type="2d" builtin="checker" rgb1="0.5 0.5 0.5" rgb2="0.55 0.55 0.55" width="100" height="100"/>
      <material name="MatPlane" reflectance="0.0" texture="texplane" texrepeat="1 1" texuniform="true"/>
  </asset>
  <worldbody>
      <geom name="floor" friction="1 .1 .1" pos="0 0 0" size="0 0 0.125" type="plane" material="MatPlane" condim="3" conaffinity="1" contype="1" group="2" rgba="0.8 0.9 0.8 1"/>
      <light cutoff="1000" diffuse="1.5 1.5 1.5" dir="-0 0 -1.3" directional="true" exponent="10" pos="0 0 10.3" specular=".1 .1 .1" castshadow="false"/>
  </worldbody>



</mujoco>
